{"name": "test_login_invalid_credentials_error_message", "status": "passed", "start": 1732447979543, "stop": 1732447979792, "uuid": "5917e0d6-6b38-4bae-89c7-ea4611c50814", "historyId": "e5774e472c142069bc9e66e164938d26", "testCaseId": "e5774e472c142069bc9e66e164938d26", "fullName": "tests.test_login_user.TestUserLogin#test_login_invalid_credentials_error_message", "labels": [{"name": "parentSuite", "value": "tests"}, {"name": "suite", "value": "test_login_user"}, {"name": "subSuite", "value": "TestUserLogin"}, {"name": "host", "value": "DESKTOP-BEKDSUT"}, {"name": "thread", "value": "11160-MainThread"}, {"name": "framework", "value": "pytest"}, {"name": "language", "value": "cpython3"}, {"name": "package", "value": "tests.test_login_user"}]}